# 10. Manejo de errores en Go

Go tiene un enfoque un poco diferente al manejo de errores en comparación con otros lenguajes de programación. En lugar de lanzar excepciones, Go utiliza valores de retorno para indicar si una función ha producido un error.

## Valores de retorno
En Go, una función puede devolver uno o varios valores. En el caso del manejo de errores, es común que una función devuelva un valor y un error.

Ejemplo:
```go
func miFuncion() (string, error) {
    // ...
}
```

En este ejemplo, la función `miFuncion()` devuelve un valor de tipo `string` y un valor de tipo `error`.

Si la función `miFuncion()` produce un error, se puede devolver un valor de error utilizando la función `fmt.Errorf()`.

Ejemplo:
```go
func miFuncion() (string, error) {
    if err := algunaOperacion(); err != nil {
        return "", fmt.Errorf("error en algunaOperacion: %s", err)
    }
    // ...
}
```

En este ejemplo, si la función `algunaOperacion()` produce un error, se devuelve un valor de error utilizando la función `fmt.Errorf()`.

## Panic y recover
En Go, la función `panic()` se utiliza para indicar que algo inesperado ha ocurrido y que no se puede continuar con la ejecución del programa. La función `recover()` se utiliza para recuperar el control después de un `panic()`.

Ejemplo:
```go
func miFuncion() {
    defer func() {
        if r := recover(); r != nil {
            log.Println("recuperado en miFuncion:", r)
        }
    }()
    // ...
    if algoInesperado {
        panic("algo inesperado ha ocurrido")
    }
    // ...
}
```

En este ejemplo, la función `miFuncion()` utiliza la función `defer` para recuperar el control después de un `panic()`. Si ocurre un `panic()`, se llama a la función anónima que utiliza `recover()` para recuperar el control y realizar alguna acción.

## Conclusiones
En Go, el manejo de errores se basa en el uso de valores de retorno y en el control explícito de errores utilizando la función `fmt.Errorf()`. La función `panic()` se utiliza en situaciones en las que no se puede continuar con la ejecución del programa y la función `recover()` se utiliza para recuperar el control después de un `panic()`.